2023-07-15 21:40:35,985 INFO    MainThread:10151 [wandb_setup.py:_flush():76] Current SDK version is 0.15.4
2023-07-15 21:40:35,985 INFO    MainThread:10151 [wandb_setup.py:_flush():76] Configure stats pid to 10151
2023-07-15 21:40:35,985 INFO    MainThread:10151 [wandb_setup.py:_flush():76] Loading settings from /home/cgm/.config/wandb/settings
2023-07-15 21:40:35,985 INFO    MainThread:10151 [wandb_setup.py:_flush():76] Loading settings from /home/cgm/code/CGM__GCLRec/pyg_code/wandb/settings
2023-07-15 21:40:35,985 INFO    MainThread:10151 [wandb_setup.py:_flush():76] Loading settings from environment variables: {}
2023-07-15 21:40:35,985 INFO    MainThread:10151 [wandb_setup.py:_flush():76] Applying setup settings: {'_disable_service': False}
2023-07-15 21:40:35,986 INFO    MainThread:10151 [wandb_setup.py:_flush():76] Inferring run settings from compute environment: {'program_relpath': 'pyg_code/main.py', 'program': '/home/cgm/code/CGM__GCLRec/pyg_code/main.py'}
2023-07-15 21:40:35,986 INFO    MainThread:10151 [wandb_init.py:_log_setup():507] Logging user logs to /home/cgm/code/CGM__GCLRec/pyg_code/wandb/run-20230715_214035-4mvidb6k/logs/debug.log
2023-07-15 21:40:35,986 INFO    MainThread:10151 [wandb_init.py:_log_setup():508] Logging internal logs to /home/cgm/code/CGM__GCLRec/pyg_code/wandb/run-20230715_214035-4mvidb6k/logs/debug-internal.log
2023-07-15 21:40:35,986 INFO    MainThread:10151 [wandb_init.py:init():547] calling init triggers
2023-07-15 21:40:35,986 INFO    MainThread:10151 [wandb_init.py:init():554] wandb.init called with sweep_config: {}
config: {'temp_tau': 0.1, 'latent_dim_rec': 64, 'num_layers': 3, 'dataset': 'yelp2018', 'lr': 0.001, 'weight_decay': 0.0001, 'seed': 2023, 'model': 'LightGCN', 'epochs': 500, 'if_multicore': 1, 'early_stop_steps': 50, 'batch_size': 2048, 'lambda1': 0.1, 'topks': [20, 40], 'test_u_batch_size': 2048, 'pop_group': 10, 'perplexity': 50, 'visual_epoch': 3, 'if_double_label': 1, 'if_tsne': 1, 'tsne_group': [0, 9], 'init_method': 'Normal', 'tsne_points': 2000, 'loss': 'simple_Adaptive', 'augment': 'No', 'alpha': 0.5, 'centroid_mode': 'eigenvector', 'commonNeighbor_mode': 'SC', 'n_cluster': 10, 'sigma_gausse': 1.0, 'adaptive_method': 'mlp', 'if_visual': 0, 'if_projector': 0, 'if_valid': 0, 'adaloss_mode': 'pos', 'if_adaptive': 1, 'freeze_mlp': 500, 'sampling': 'uiij', 'comment': '_', 'project': 'GCLRec_No_Valid', 'name': 'mixup', 'tag': ['mixup'], 'notes': '3InfoNCE', 'group': 'Ours', 'job_type': 'yelp2018', 'c': 'testing', 'device': device(type='cuda'), 'cores': 10}
2023-07-15 21:40:35,986 INFO    MainThread:10151 [wandb_init.py:init():596] starting backend
2023-07-15 21:40:35,986 INFO    MainThread:10151 [wandb_init.py:init():600] setting up manager
2023-07-15 21:40:35,987 INFO    MainThread:10151 [backend.py:_multiprocessing_setup():106] multiprocessing start_methods=fork,spawn,forkserver, using: spawn
2023-07-15 21:40:35,988 INFO    MainThread:10151 [wandb_init.py:init():606] backend started and connected
2023-07-15 21:40:35,992 INFO    MainThread:10151 [wandb_init.py:init():703] updated telemetry
2023-07-15 21:40:35,994 INFO    MainThread:10151 [wandb_init.py:init():736] communicating run to backend with 60.0 second timeout
2023-07-15 21:40:46,494 WARNING MainThread:10151 [wandb_init.py:init():1174] interrupted
Traceback (most recent call last):
  File "/home/cgm/anaconda3/envs/cgm/lib/python3.10/site-packages/wandb/sdk/wandb_init.py", line 1152, in init
    run = wi.init()
  File "/home/cgm/anaconda3/envs/cgm/lib/python3.10/site-packages/wandb/sdk/wandb_init.py", line 739, in init
    result = run_init_handle.wait(
  File "/home/cgm/anaconda3/envs/cgm/lib/python3.10/site-packages/wandb/sdk/lib/mailbox.py", line 283, in wait
    found, abandoned = self._slot._get_and_clear(timeout=wait_timeout)
  File "/home/cgm/anaconda3/envs/cgm/lib/python3.10/site-packages/wandb/sdk/lib/mailbox.py", line 130, in _get_and_clear
    if self._wait(timeout=timeout):
  File "/home/cgm/anaconda3/envs/cgm/lib/python3.10/site-packages/wandb/sdk/lib/mailbox.py", line 126, in _wait
    return self._event.wait(timeout=timeout)
  File "/home/cgm/anaconda3/envs/cgm/lib/python3.10/threading.py", line 607, in wait
    signaled = self._cond.wait(timeout)
  File "/home/cgm/anaconda3/envs/cgm/lib/python3.10/threading.py", line 324, in wait
    gotit = waiter.acquire(True, timeout)
KeyboardInterrupt
2023-07-15 21:41:04,603 INFO    Thread-1 (wrapped_target):10151 [retry.py:__call__():172] Retry attempt failed:
Traceback (most recent call last):
  File "/home/cgm/anaconda3/envs/cgm/lib/python3.10/site-packages/urllib3/connection.py", line 174, in _new_conn
    conn = connection.create_connection(
  File "/home/cgm/anaconda3/envs/cgm/lib/python3.10/site-packages/urllib3/util/connection.py", line 95, in create_connection
    raise err
  File "/home/cgm/anaconda3/envs/cgm/lib/python3.10/site-packages/urllib3/util/connection.py", line 85, in create_connection
    sock.connect(sa)
TimeoutError: timed out

During handling of the above exception, another exception occurred:

Traceback (most recent call last):
  File "/home/cgm/anaconda3/envs/cgm/lib/python3.10/site-packages/urllib3/connectionpool.py", line 714, in urlopen
    httplib_response = self._make_request(
  File "/home/cgm/anaconda3/envs/cgm/lib/python3.10/site-packages/urllib3/connectionpool.py", line 403, in _make_request
    self._validate_conn(conn)
  File "/home/cgm/anaconda3/envs/cgm/lib/python3.10/site-packages/urllib3/connectionpool.py", line 1053, in _validate_conn
    conn.connect()
  File "/home/cgm/anaconda3/envs/cgm/lib/python3.10/site-packages/urllib3/connection.py", line 363, in connect
    self.sock = conn = self._new_conn()
  File "/home/cgm/anaconda3/envs/cgm/lib/python3.10/site-packages/urllib3/connection.py", line 179, in _new_conn
    raise ConnectTimeoutError(
urllib3.exceptions.ConnectTimeoutError: (<urllib3.connection.HTTPSConnection object at 0x7fc16b74a770>, 'Connection to api.wandb.ai timed out. (connect timeout=10)')

During handling of the above exception, another exception occurred:

Traceback (most recent call last):
  File "/home/cgm/anaconda3/envs/cgm/lib/python3.10/site-packages/requests/adapters.py", line 487, in send
    resp = conn.urlopen(
  File "/home/cgm/anaconda3/envs/cgm/lib/python3.10/site-packages/urllib3/connectionpool.py", line 798, in urlopen
    retries = retries.increment(
  File "/home/cgm/anaconda3/envs/cgm/lib/python3.10/site-packages/urllib3/util/retry.py", line 592, in increment
    raise MaxRetryError(_pool, url, error or ResponseError(cause))
urllib3.exceptions.MaxRetryError: HTTPSConnectionPool(host='api.wandb.ai', port=443): Max retries exceeded with url: /graphql (Caused by ConnectTimeoutError(<urllib3.connection.HTTPSConnection object at 0x7fc16b74a770>, 'Connection to api.wandb.ai timed out. (connect timeout=10)'))

During handling of the above exception, another exception occurred:

Traceback (most recent call last):
  File "/home/cgm/anaconda3/envs/cgm/lib/python3.10/site-packages/wandb/sdk/lib/retry.py", line 131, in __call__
    result = self._call_fn(*args, **kwargs)
  File "/home/cgm/anaconda3/envs/cgm/lib/python3.10/site-packages/wandb/sdk/internal/internal_api.py", line 320, in execute
    return self.client.execute(*args, **kwargs)  # type: ignore
  File "/home/cgm/anaconda3/envs/cgm/lib/python3.10/site-packages/wandb/vendor/gql-0.2.0/wandb_gql/client.py", line 52, in execute
    result = self._get_result(document, *args, **kwargs)
  File "/home/cgm/anaconda3/envs/cgm/lib/python3.10/site-packages/wandb/vendor/gql-0.2.0/wandb_gql/client.py", line 60, in _get_result
    return self.transport.execute(document, *args, **kwargs)
  File "/home/cgm/anaconda3/envs/cgm/lib/python3.10/site-packages/wandb/sdk/lib/gql_request.py", line 55, in execute
    request = self.session.post(self.url, **post_args)
  File "/home/cgm/anaconda3/envs/cgm/lib/python3.10/site-packages/requests/sessions.py", line 635, in post
    return self.request("POST", url, data=data, json=json, **kwargs)
  File "/home/cgm/anaconda3/envs/cgm/lib/python3.10/site-packages/requests/sessions.py", line 587, in request
    resp = self.send(prep, **send_kwargs)
  File "/home/cgm/anaconda3/envs/cgm/lib/python3.10/site-packages/requests/sessions.py", line 701, in send
    r = adapter.send(request, **kwargs)
  File "/home/cgm/anaconda3/envs/cgm/lib/python3.10/site-packages/requests/adapters.py", line 508, in send
    raise ConnectTimeout(e, request=request)
requests.exceptions.ConnectTimeout: HTTPSConnectionPool(host='api.wandb.ai', port=443): Max retries exceeded with url: /graphql (Caused by ConnectTimeoutError(<urllib3.connection.HTTPSConnection object at 0x7fc16b74a770>, 'Connection to api.wandb.ai timed out. (connect timeout=10)'))
